<robot name="diff_robot">
    <link name="base_link">  
    </link>
    <joint name="base_joint" type="fixed">
        <parent link="base_link"/>
        <child link="frame_link"/>
        <origin xyz="-0.1 0.0 0.0" rpy="0.0 0.0 0.0"/>
    </joint>


    <link name="frame_link">
        <visual>
            <geometry>
                <box size="0.4 0.3 0.1"/>
            </geometry>
            <origin xyz="0.2 0.0 0.05" rpy="0.0 0.0 0.0"/>
            <material name="orange">
                <color rgba="1.0 0.64 0.0 1.0"/>
            </material>
        </visual>
        <inertial>
            <mass value="4.0"/>
            <origin xyz="0.2 0.0 0.05"/>
            <inertia ixx="0.1" ixy="0.0" ixz="0.0" iyy="0.1" iyz="0.0" izz="0.1"/>
        </inertial>
        <collision>
            <geometry>
                <box size="0.4 0.3 0.1"/>
            </geometry>
            <origin xyz="0.2 0.0 0.075" rpy="0.0 0.0 0.0"/>
        </collision>
    </link>



    <joint name="left_wheel_joint" type="continuous">
        <parent link="base_link"/>
        <child link="left_wheel_link"/>
        <origin xyz="0.0 0.17 0.0" rpy="-1.57 0.0 0.0"/>
        <axis xyz="0.0 0.0 1.0"/>   
    </joint>
    <link name="left_wheel_link">
        <visual>
            <geometry>
                <cylinder radius="0.1" length="0.05"/>
            </geometry>
            <origin xyz="0.0 0.0 0.0" rpy="0 0.0 0.0"/>
            <material name="white">
                <color rgba="1.0 1.0 1.0 1.0"/>
            </material>
        </visual>
        <inertial>
            <mass value="2.0"/>
            <origin xyz="0.0 0.0 0.0"/>
            <inertia ixx="0.1" ixy="0.0" ixz="0.0" iyy="0.1" iyz="0.0" izz="0.1"/>
        </inertial>
        <collision>
            <geometry>
                <cylinder radius="0.1" length="0.05"/>
            </geometry>
            <origin xyz="0.0 0.0 0.0" rpy="0 0.0 0.0"/>
        </collision>
    </link>

    <joint name="right_wheel_joint" type="continuous">
        <parent link="base_link"/>
        <child link="right_wheel_link"/>
        <origin xyz="0.0 -0.17 0.0" rpy="-1.57 0.0 0.0"/>
        <axis xyz="0.0 0.0 1.0"/>   
    </joint>
    <link name="right_wheel_link">
        <visual>
            <geometry>
                <cylinder radius="0.1" length="0.05"/>
            </geometry>
            <origin xyz="0.0 0.0 0.0" rpy="0 0.0 0.0"/>
            <material name="white">
                <color rgba="1.0 1.0 1.0 1.0"/>
            </material>
        </visual>
        <inertial>
            <mass value="2.0"/>
            <origin xyz="0.0 0.0 0.0"/>
            <inertia ixx="0.1" ixy="0.0" ixz="0.0" iyy="0.1" iyz="0.0" izz="0.1"/>
        </inertial>
        <collision>
            <geometry>
                <cylinder radius="0.1" length="0.05"/>
            </geometry>
            <origin xyz="0.0 0.0 0.0" rpy="0 0.0 0.0"/>
        </collision>
    </link>
    <joint name="caster_joint" type="fixed">
        <parent link="base_link"/>
        <child link="caster_link"/>
        <origin xyz="0.2 0.0 0.0"/>        
    </joint>
    <link name="caster_link">
        <visual>
            <geometry>
                <sphere radius="0.1"/>
            </geometry>
            <origin xyz="0.0 0.0 0.0"/>
            <material name="black">
                <color rgba="0.0 0.0 0.0 1.0"/>
            </material>
        </visual>
        <inertial>
            <mass value="1e-5"/>
            <origin xyz="0.0 0.0 0.0"/>
            <inertia ixx="1e-6" ixy="0" ixz="0" iyy="1e-6" iyz="0" izz="1e-6"/>
        </inertial>
        <collision>
            <geometry>
                <sphere radius="0.1"/>
            </geometry>
            <origin xyz="0.0 0.0 0.0"/>
        </collision>
    </link>



  <link name="tru_laser_link">
        <inertial>
            <origin xyz="0.0 0.0 0.0" rpy="0.0 0.0 0.0"/>
            <mass value="1.0"/>
            <inertia ixx="0.01" ixy="0.0" ixz="0.0" iyy="0.01" iyz="0.0" izz="0.01"/>
        </inertial>

        <visual>
            <origin xyz="0.0 0.0 0.05" rpy="0.0 0.0 0.0"/>
            <geometry>
                <cylinder radius="0.08" length="0.1"/>
            </geometry>
            <material name="red">
                <color rgba="1.0 0.0 0.0 1.0"/>
            </material>
        </visual>

        <collision>
            <origin xyz="0.0 0.0 0.0" rpy="0.0 0.0 0.0"/>
            <geometry>
                <cylinder radius="0.08" length="0.15"/>
            </geometry>
        </collision>
    </link>
    <joint name="tru_laser_joint" type="fixed">
        <origin xyz="0.1 0.0 0.1" rpy="0.0 0.0 0.0"/>
        <parent link="base_link"/>
        <child link="tru_laser_link"/>
    </joint>


    <joint name="laser_joint" type="fixed">
        <origin xyz="0.0 0.0 0.1" rpy="0.0 0.0 0.0"/>
        <parent link="tru_laser_link"/>
        <child link="laser_link"/>
    </joint>
    <link name="laser_link">
        <inertial>
            <origin xyz="0.0 0.0 0.0" rpy="0.0 0.0 0.0"/>
            <mass value="1.0"/>
            <inertia ixx="0.01" ixy="0.0" ixz="0.0" iyy="0.01" iyz="0.0" izz="0.01"/>
        </inertial>
        <visual>
            <origin xyz="0.0 0.0 0.02" rpy="0.0 0.0 0.0"/>
            <geometry>
                <cylinder radius="0.05" length="0.04"/>
            </geometry>
            <material name="yellow">
                <color rgba="1.0 1.0 0.0 1.0"/>
            </material>
        </visual>
        <collision>
            <origin xyz="0.0 0.0 0.02" rpy="0.0 0.0 0.0"/>
            <geometry>
                <cylinder radius="0.05" length="0.04"/>
            </geometry>
        </collision>
    </link>


    <link name="camera_link">
        <visual>
            <geometry>
                <box size="0.03 0.1 0.08"/>
            </geometry>
            <origin xyz="0.0 0.0 0.0"/>
            <material name="green">
                <color rgba="0.0 1.0 0.0 1.0"/>
            </material>
        </visual>
        <inertial>
            <mass value="1e-5" />
            <origin xyz="0 0 0" rpy="0 0 0"/>
            <inertia ixx="1e-6" ixy="0" ixz="0" iyy="1e-6" iyz="0" izz="1e-6" />
        </inertial>
        <collision>
            <geometry>
                <box size="0.03 0.1 0.08"/>
            </geometry>
            <origin xyz="0.0 0.0 0.0"/>
        </collision>
    </link>
    <joint name="camera_joint" type="fixed">
        <parent link="base_link"/>
        <child link="camera_link"/>
        <origin xyz="0.28 0.0 0.14" rpy="0.0 0.26 0.0"/>
    </joint>
   

    
    <!-- Gazebo -->
    <gazebo reference="frame_link">
        <material>Gazebo/Orange</material>
    </gazebo>
    <gazebo reference="left_wheel_link">
        <material>Gazebo/White</material>
    </gazebo>
    <gazebo reference="right_wheel_link">
        <material>Gazebo/White</material>
    </gazebo>
    <gazebo reference="caster_link">
        <mu1>0.2</mu1>
        <mu2>0.2</mu2>
        <material>Gazebo/Green</material>
    </gazebo>
    <gazebo reference="tru_laser_link">
        <material>Gazebo/Red</material>
    </gazebo>

    <!--laser-->
    <gazebo reference="laser_link">
        <material>Gazebo/Yellow</material>
        <sensor type="ray" name="laser_sensor">
        <pose>0 0 0 0 0 0</pose>
        <visualize>false</visualize>
        <update_rate>40</update_rate>
        <ray>
            <scan>
                <horizontal>
                    <samples>720</samples>
                    <resolution>1</resolution>
                    <min_angle>-3.14</min_angle>
                    <max_angle>3.14</max_angle>
                </horizontal>
        </scan>
        <range>
          <min>0.10</min>
          <max>30.0</max>
          <resolution>0.01</resolution>
        </range>
        <noise>
          <type>gaussian</type>
          <mean>0.0</mean>
          <stddev>0.01</stddev>
        </noise>
      </ray>
      <plugin name="laser_controller" filename="libgazebo_ros_laser.so">
        <topicName>/my_diff_robot/laser/scan</topicName>
        <frameName>laser_link</frameName>
      </plugin>
    </sensor>
  </gazebo>
    <!-- camera -->
    <gazebo reference="camera_link">
        <material>Gazebo/Green</material>
        <sensor type="camera" name="camera1">
        <update_rate>30.0</update_rate>
        <camera name="head">
            <horizontal_fov>1.3962634</horizontal_fov>
            <image>
                <width>800</width>
                <height>800</height>
                <format>R8G8B8</format>
            </image>
            <clip>
                <near>0.02</near>
                <far>300</far>
            </clip>
            <noise>
            <type>gaussian</type>
                <!-- Noise is sampled independently per pixel on each frame.
                    That pixel's noise value is added to each of its color
                    channels, which at that point lie in the range [0,1]. -->
                <mean>0.0</mean>
                <stddev>0.007</stddev>
            </noise>
        </camera>
        <plugin name="camera_controller" filename="libgazebo_ros_camera.so">
            <alwaysOn>true</alwaysOn>
            <updateRate>0.0</updateRate>
            <cameraName>my_robot/camera1</cameraName>
            <imageTopicName>image_raw</imageTopicName>
            <cameraInfoTopicName>camera_info</cameraInfoTopicName>
            <frameName>camera_link</frameName>
            <hackBaseline>0.07</hackBaseline>
            <distortionK1>0.0</distortionK1>
            <distortionK2>0.0</distortionK2>
            <distortionK3>0.0</distortionK3>
            <distortionT1>0.0</distortionT1>
            <distortionT2>0.0</distortionT2>
        </plugin>
        </sensor>
    </gazebo>

 <!-- Transmission -->
    <transmission name="tran1">
        <type>transmission_interface/SimpleTransmission</type>
        <joint name="left_wheel_joint">
            <hardwareInterface>hardware_interface/EffortJointInterface</hardwareInterface>
        </joint>
        <actuator name="motor1">
            <hardwareInterface>hardware_interface/EffortJointInterface</hardwareInterface>
            <mechanicalReduction>1</mechanicalReduction>
        </actuator>
  </transmission>

  <transmission name="tran2">
    <type>transmission_interface/SimpleTransmission</type>
    <joint name="right_wheel_joint">
        <hardwareInterface>hardware_interface/EffortJointInterface</hardwareInterface>
    </joint>
    <actuator name="motor2">
        <hardwareInterface>hardware_interface/EffortJointInterface</hardwareInterface>
        <mechanicalReduction>1</mechanicalReduction>
    </actuator>
  </transmission>
    
    <!--gazebo>
        <plugin name="gazebo_ros_control" filename="libgazebo_ros_control.so">
            <robotNamespace>/my_diffbot</robotNamespace>
        </plugin>
    </gazebo-->    
  
  <gazebo>
  <plugin name="gazebo_ros_control" filename="libgazebo_ros_diff_drive.so">
    <legacyMode>false</legacyMode>
    <updateRate>50</updateRate>
    <leftJoint>left_wheel_joint</leftJoint>
    <rightJoint>right_wheel_joint</rightJoint>
    <wheelSeparation>0.33</wheelSeparation>
    <wheelDiameter>0.12</wheelDiameter>
    <wheelAcceleration>1.0</wheelAcceleration>
    <wheelTorque>20</wheelTorque>
    <commandTopic>cmd_vel</commandTopic>
    <odometryTopic>odom</odometryTopic>
    <odometryFrame>odom</odometryFrame>
    <robotBaseFrame>base_link</robotBaseFrame>
    <odometrySource>1</odometrySource>
    <publishWheelTF>true</publishWheelTF>
    <publishOdom>true</publishOdom>
    <publishWheelJointState>true</publishWheelJointState>
    
  </plugin>
</gazebo>

</robot>